[2024-12-31 16:18:40,702][flwr][WARNING] - DEPRECATED FEATURE: flwr.simulation.start_simulation() is deprecated.
	Instead, use the `flwr run` CLI command to start a local simulation in your Flower app, as shown for example below:

		$ flwr new  # Create a new Flower app from a template

		$ flwr run  # Run the Flower app in Simulation Mode

	Using `start_simulation()` is deprecated.

            This is a deprecated feature. It will be removed
            entirely in future versions of Flower.
        
[2024-12-31 16:18:40,702][flwr][INFO] - Starting Flower simulation, config: num_rounds=10, no round_timeout
[2024-12-31 16:18:45,433][flwr][INFO] - Flower VCE: Ray initialized with resources: {'CPU': 8.0, 'object_store_memory': 3703691673.0, 'memory': 7407383348.0, 'node:192.168.100.172': 1.0, 'node:__internal_head__': 1.0}
[2024-12-31 16:18:45,434][flwr][INFO] - Optimize your simulation with Flower VCE: https://flower.ai/docs/framework/how-to-run-simulations.html
[2024-12-31 16:18:45,434][flwr][INFO] - Flower VCE: Resources for each Virtual Client: {'num_cpus': 2, 'num_gpus': 0.0}
[2024-12-31 16:18:45,452][flwr][INFO] - Flower VCE: Creating VirtualClientEngineActorPool with 4 actors
[2024-12-31 16:18:45,453][flwr][INFO] - [INIT]
[2024-12-31 16:18:45,454][flwr][INFO] - Requesting initial parameters from one random client
[2024-12-31 16:18:49,842][flwr][ERROR] - Traceback (most recent call last):
  File "/home/tulio/miniconda3/envs/flenv/lib/python3.9/site-packages/flwr/simulation/ray_transport/ray_client_proxy.py", line 94, in _submit_job
    out_mssg, updated_context = self.actor_pool.get_client_result(
  File "/home/tulio/miniconda3/envs/flenv/lib/python3.9/site-packages/flwr/simulation/ray_transport/ray_actor.py", line 399, in get_client_result
    return self._fetch_future_result(cid)
  File "/home/tulio/miniconda3/envs/flenv/lib/python3.9/site-packages/flwr/simulation/ray_transport/ray_actor.py", line 280, in _fetch_future_result
    res_cid, out_mssg, updated_context = ray.get(
  File "/home/tulio/miniconda3/envs/flenv/lib/python3.9/site-packages/ray/_private/auto_init_hook.py", line 21, in auto_init_wrapper
    return fn(*args, **kwargs)
  File "/home/tulio/miniconda3/envs/flenv/lib/python3.9/site-packages/ray/_private/client_mode_hook.py", line 103, in wrapper
    return func(*args, **kwargs)
  File "/home/tulio/miniconda3/envs/flenv/lib/python3.9/site-packages/ray/_private/worker.py", line 2667, in get
    values, debugger_breakpoint = worker.get_objects(object_refs, timeout=timeout)
  File "/home/tulio/miniconda3/envs/flenv/lib/python3.9/site-packages/ray/_private/worker.py", line 864, in get_objects
    raise value.as_instanceof_cause()
ray.exceptions.RayTaskError(ClientAppException): [36mray::ClientAppActor.run()[39m (pid=21175, ip=192.168.100.172, actor_id=ed500ac20f897702cb5ba7ce01000000, repr=<flwr.simulation.ray_transport.ray_actor.ClientAppActor object at 0x7bdcc3968910>)
  File "/home/tulio/miniconda3/envs/flenv/lib/python3.9/site-packages/flwr/client/client_app.py", line 143, in __call__
    return self._call(message, context)
  File "/home/tulio/miniconda3/envs/flenv/lib/python3.9/site-packages/flwr/client/client_app.py", line 126, in ffn
    out_message = handle_legacy_message_from_msgtype(
  File "/home/tulio/miniconda3/envs/flenv/lib/python3.9/site-packages/flwr/client/message_handler/message_handler.py", line 96, in handle_legacy_message_from_msgtype
    client = client_fn(context)
  File "/home/tulio/repos/ProjetoAnaliseMobilidade/client.py", line 165, in client_fn
    cid = int(context.cid)  # context.cid is a string, convert it to int
AttributeError: 'Context' object has no attribute 'cid'

The above exception was the direct cause of the following exception:

[36mray::ClientAppActor.run()[39m (pid=21175, ip=192.168.100.172, actor_id=ed500ac20f897702cb5ba7ce01000000, repr=<flwr.simulation.ray_transport.ray_actor.ClientAppActor object at 0x7bdcc3968910>)
  File "/home/tulio/miniconda3/envs/flenv/lib/python3.9/site-packages/flwr/simulation/ray_transport/ray_actor.py", line 64, in run
    raise ClientAppException(str(ex)) from ex
flwr.client.client_app.ClientAppException: 
Exception ClientAppException occurred. Message: 'Context' object has no attribute 'cid'

[2024-12-31 16:18:49,842][flwr][ERROR] - [36mray::ClientAppActor.run()[39m (pid=21175, ip=192.168.100.172, actor_id=ed500ac20f897702cb5ba7ce01000000, repr=<flwr.simulation.ray_transport.ray_actor.ClientAppActor object at 0x7bdcc3968910>)
  File "/home/tulio/miniconda3/envs/flenv/lib/python3.9/site-packages/flwr/client/client_app.py", line 143, in __call__
    return self._call(message, context)
  File "/home/tulio/miniconda3/envs/flenv/lib/python3.9/site-packages/flwr/client/client_app.py", line 126, in ffn
    out_message = handle_legacy_message_from_msgtype(
  File "/home/tulio/miniconda3/envs/flenv/lib/python3.9/site-packages/flwr/client/message_handler/message_handler.py", line 96, in handle_legacy_message_from_msgtype
    client = client_fn(context)
  File "/home/tulio/repos/ProjetoAnaliseMobilidade/client.py", line 165, in client_fn
    cid = int(context.cid)  # context.cid is a string, convert it to int
AttributeError: 'Context' object has no attribute 'cid'

The above exception was the direct cause of the following exception:

[36mray::ClientAppActor.run()[39m (pid=21175, ip=192.168.100.172, actor_id=ed500ac20f897702cb5ba7ce01000000, repr=<flwr.simulation.ray_transport.ray_actor.ClientAppActor object at 0x7bdcc3968910>)
  File "/home/tulio/miniconda3/envs/flenv/lib/python3.9/site-packages/flwr/simulation/ray_transport/ray_actor.py", line 64, in run
    raise ClientAppException(str(ex)) from ex
flwr.client.client_app.ClientAppException: 
Exception ClientAppException occurred. Message: 'Context' object has no attribute 'cid'
[2024-12-31 16:18:49,842][flwr][ERROR] - [36mray::ClientAppActor.run()[39m (pid=21175, ip=192.168.100.172, actor_id=ed500ac20f897702cb5ba7ce01000000, repr=<flwr.simulation.ray_transport.ray_actor.ClientAppActor object at 0x7bdcc3968910>)
  File "/home/tulio/miniconda3/envs/flenv/lib/python3.9/site-packages/flwr/client/client_app.py", line 143, in __call__
    return self._call(message, context)
  File "/home/tulio/miniconda3/envs/flenv/lib/python3.9/site-packages/flwr/client/client_app.py", line 126, in ffn
    out_message = handle_legacy_message_from_msgtype(
  File "/home/tulio/miniconda3/envs/flenv/lib/python3.9/site-packages/flwr/client/message_handler/message_handler.py", line 96, in handle_legacy_message_from_msgtype
    client = client_fn(context)
  File "/home/tulio/repos/ProjetoAnaliseMobilidade/client.py", line 165, in client_fn
    cid = int(context.cid)  # context.cid is a string, convert it to int
AttributeError: 'Context' object has no attribute 'cid'

The above exception was the direct cause of the following exception:

[36mray::ClientAppActor.run()[39m (pid=21175, ip=192.168.100.172, actor_id=ed500ac20f897702cb5ba7ce01000000, repr=<flwr.simulation.ray_transport.ray_actor.ClientAppActor object at 0x7bdcc3968910>)
  File "/home/tulio/miniconda3/envs/flenv/lib/python3.9/site-packages/flwr/simulation/ray_transport/ray_actor.py", line 64, in run
    raise ClientAppException(str(ex)) from ex
flwr.client.client_app.ClientAppException: 
Exception ClientAppException occurred. Message: 'Context' object has no attribute 'cid'
[2024-12-31 16:18:49,843][flwr][ERROR] - Traceback (most recent call last):
  File "/home/tulio/miniconda3/envs/flenv/lib/python3.9/site-packages/flwr/simulation/legacy_app.py", line 359, in start_simulation
    hist = run_fl(
  File "/home/tulio/miniconda3/envs/flenv/lib/python3.9/site-packages/flwr/server/server.py", line 492, in run_fl
    hist, elapsed_time = server.fit(
  File "/home/tulio/miniconda3/envs/flenv/lib/python3.9/site-packages/flwr/server/server.py", line 93, in fit
    self.parameters = self._get_initial_parameters(server_round=0, timeout=timeout)
  File "/home/tulio/miniconda3/envs/flenv/lib/python3.9/site-packages/flwr/server/server.py", line 284, in _get_initial_parameters
    get_parameters_res = random_client.get_parameters(
  File "/home/tulio/miniconda3/envs/flenv/lib/python3.9/site-packages/flwr/simulation/ray_transport/ray_client_proxy.py", line 168, in get_parameters
    message_out = self._submit_job(message, timeout)
  File "/home/tulio/miniconda3/envs/flenv/lib/python3.9/site-packages/flwr/simulation/ray_transport/ray_client_proxy.py", line 108, in _submit_job
    raise ex
  File "/home/tulio/miniconda3/envs/flenv/lib/python3.9/site-packages/flwr/simulation/ray_transport/ray_client_proxy.py", line 94, in _submit_job
    out_mssg, updated_context = self.actor_pool.get_client_result(
  File "/home/tulio/miniconda3/envs/flenv/lib/python3.9/site-packages/flwr/simulation/ray_transport/ray_actor.py", line 399, in get_client_result
    return self._fetch_future_result(cid)
  File "/home/tulio/miniconda3/envs/flenv/lib/python3.9/site-packages/flwr/simulation/ray_transport/ray_actor.py", line 280, in _fetch_future_result
    res_cid, out_mssg, updated_context = ray.get(
  File "/home/tulio/miniconda3/envs/flenv/lib/python3.9/site-packages/ray/_private/auto_init_hook.py", line 21, in auto_init_wrapper
    return fn(*args, **kwargs)
  File "/home/tulio/miniconda3/envs/flenv/lib/python3.9/site-packages/ray/_private/client_mode_hook.py", line 103, in wrapper
    return func(*args, **kwargs)
  File "/home/tulio/miniconda3/envs/flenv/lib/python3.9/site-packages/ray/_private/worker.py", line 2667, in get
    values, debugger_breakpoint = worker.get_objects(object_refs, timeout=timeout)
  File "/home/tulio/miniconda3/envs/flenv/lib/python3.9/site-packages/ray/_private/worker.py", line 864, in get_objects
    raise value.as_instanceof_cause()
ray.exceptions.RayTaskError(ClientAppException): [36mray::ClientAppActor.run()[39m (pid=21175, ip=192.168.100.172, actor_id=ed500ac20f897702cb5ba7ce01000000, repr=<flwr.simulation.ray_transport.ray_actor.ClientAppActor object at 0x7bdcc3968910>)
  File "/home/tulio/miniconda3/envs/flenv/lib/python3.9/site-packages/flwr/client/client_app.py", line 143, in __call__
    return self._call(message, context)
  File "/home/tulio/miniconda3/envs/flenv/lib/python3.9/site-packages/flwr/client/client_app.py", line 126, in ffn
    out_message = handle_legacy_message_from_msgtype(
  File "/home/tulio/miniconda3/envs/flenv/lib/python3.9/site-packages/flwr/client/message_handler/message_handler.py", line 96, in handle_legacy_message_from_msgtype
    client = client_fn(context)
  File "/home/tulio/repos/ProjetoAnaliseMobilidade/client.py", line 165, in client_fn
    cid = int(context.cid)  # context.cid is a string, convert it to int
AttributeError: 'Context' object has no attribute 'cid'

The above exception was the direct cause of the following exception:

[36mray::ClientAppActor.run()[39m (pid=21175, ip=192.168.100.172, actor_id=ed500ac20f897702cb5ba7ce01000000, repr=<flwr.simulation.ray_transport.ray_actor.ClientAppActor object at 0x7bdcc3968910>)
  File "/home/tulio/miniconda3/envs/flenv/lib/python3.9/site-packages/flwr/simulation/ray_transport/ray_actor.py", line 64, in run
    raise ClientAppException(str(ex)) from ex
flwr.client.client_app.ClientAppException: 
Exception ClientAppException occurred. Message: 'Context' object has no attribute 'cid'

[2024-12-31 16:18:49,843][flwr][ERROR] - Your simulation crashed :(. This could be because of several reasons. The most common are: 
	 > Sometimes, issues in the simulation code itself can cause crashes. It's always a good idea to double-check your code for any potential bugs or inconsistencies that might be contributing to the problem. For example: 
		 - You might be using a class attribute in your clients that hasn't been defined.
		 - There could be an incorrect method call to a 3rd party library (e.g., PyTorch).
		 - The return types of methods in your clients/strategies might be incorrect.
	 > Your system couldn't fit a single VirtualClient: try lowering `client_resources`.
	 > All the actors in your pool crashed. This could be because: 
		 - You clients hit an out-of-memory (OOM) error and actors couldn't recover from it. Try launching your simulation with more generous `client_resources` setting (i.e. it seems {'num_cpus': 2, 'num_gpus': 0.0} is not enough for your run). Use fewer concurrent actors. 
		 - You were running a multi-node simulation and all worker nodes disconnected. The head node might still be alive but cannot accommodate any actor with resources: {'num_cpus': 2, 'num_gpus': 0.0}.
Take a look at the Flower simulation examples for guidance <https://flower.ai/docs/framework/how-to-run-simulations.html>.
